import pytest
import pandas as pd
import numpy as np
from unittest.mock import patch, Mock
import asyncio

class TestErrorHandling:
    """Testes para tratamento de erros e casos extremos."""
    
    @pytest.mark.asyncio
    async def test_empty_dataset_handling(self):
        """Testa tratamento de datasets vazios."""
        from src.tools.metrics_tool import MetricsCalculatorTool
        
        metrics_tool = MetricsCalculatorTool()
        empty_df = pd.DataFrame()
        
        # Todas as métricas devem lidar graciosamente com dados vazios
        result = await metrics_tool.calculate_mortality_rate(empty_df, "2024-01-01")
        assert result['rate'] == 0.0
        
        result = await metrics_tool.calculate_icu_occupancy_rate(empty_df, "2024-01-01")
        assert result['rate'] == 0.0
        
        result = await metrics_tool.calculate_vaccination_rate(empty_df, "2024-01-01")
        assert result['rate'] == 0.0
    
    @pytest.mark.asyncio
    async def test_corrupted_data_handling(self):
        """Testa tratamento de dados corrompidos."""
        from src.data.processor import SRAGDataProcessor
        
        # Criar dados corrompidos
        corrupted_data = pd.DataFrame({
            'DT_NOTIFIC': ['invalid_date', '32/13/2024', None],
            'NU_IDADE_N': ['not_a_number', -999, 'abc'],
            'CS_SEXO': [None, 'INVALID', 123],
            'EVOLUCAO': ['', 'WRONG', None]
        })
        
        processor = SRAGDataProcessor()
        
        # Processador deve lidar com dados corrompidos sem crash
        try:
            result = await processor.load_and_process(
                start_date="2023-01-01",
                end_date="2023-12-31"
            )
            # Se chegou aqui, tratamento de erro está funcionando
        except FileNotFoundError:
            # Esperado quando arquivo não existe
            pass
        except Exception as e:
            # Outras exceções devem ser específicas e tratadas
            pytest.fail(f"Erro não tratado adequadamente: {e}")
    
    def test_network_timeout_simulation(self):
        """Testa tratamento de timeout de rede."""
        from src.tools.news_tool import NewsSearchTool
        
        news_tool = NewsSearchTool()
        
        # Simular timeout
        with patch('aiohttp.ClientSession.get') as mock_get:
            mock_get.side_effect = asyncio.TimeoutError("Request timeout")
            
            # Tool deve lidar graciosamente com timeout
            try:
                result = asyncio.run(news_tool._search_news_api(30))
                assert isinstance(result, list)  # Deve retornar lista vazia
                assert len(result) == 0
            except Exception as e:
                pytest.fail(f"Timeout não tratado adequadamente: {e}")
    
    def test_invalid_configuration_handling(self):
        """Testa tratamento de configurações inválidas."""
        from src.config.settings import SRAGSettings
        
        # Testar com variáveis de ambiente inválidas
        with patch.dict('os.environ', {
            'MAX_WORKERS': 'not_a_number',
            'TIMEOUT_SECONDS': 'invalid',
            'LOG_LEVEL': 'INVALID_LEVEL'
        }):
            # Settings devem usar valores padrão quando inválidos
            settings = SRAGSettings()
            
            assert isinstance(settings.system.max_workers, int)
            assert isinstance(settings.system.timeout_seconds, int)
            assert settings.system.log_level.value in ['DEBUG', 'INFO', 'WARNING', 'ERROR', 'CRITICAL']
    
    def test_file_permission_errors(self, tmp_path):
        """Testa tratamento de erros de permissão de arquivo."""
        from src.data.processor import SRAGDataProcessor
        
        # Criar arquivo sem permissão de leitura
        restricted_file = tmp_path / "restricted.csv"
        restricted_file.write_text("test,data\n1,2")
        restricted_file.chmod(0o000)  # Sem permissões
        
        processor = SRAGDataProcessor()
        
        try:
            # Deve falhar graciosamente
            result = asyncio.run(processor.load_and_process(str(restricted_file)))
            pytest.fail("Deveria ter falhado com erro de permissão")
        except (PermissionError, OSError):
            # Esperado
            pass
        finally:
            # Restaurar permissões para limpeza
            try:
                restricted_file.chmod(0o644)
            except:
                pass
    
    @pytest.mark.asyncio
    async def test_api_rate_limit_handling(self):
        """Testa tratamento de rate limiting de APIs."""
        from src.tools.news_tool import NewsSearchTool
        
        news_tool = NewsSearchTool()
        
        # Simular resposta de rate limit
        with patch('aiohttp.ClientSession.get') as mock_get:
            mock_response = Mock()
            mock_response.status = 429  # Too Many Requests
            mock_response.json = Mock(return_value={'error': 'Rate limit exceeded'})
            mock_get.return_value.__aenter__.return_value = mock_response
            
            # Tool deve lidar com rate limiting
            result = await news_tool._search_news_api(30)
            assert isinstance(result, list)
            assert len(result) == 0  # Deve retornar vazio quando rate limited
    
    def test_memory_pressure_handling(self):
        """Testa comportamento sob pressão de memória."""
        from src.data.processor import SRAGDataProcessor
        
        # Criar dataset que simula uso alto de memória
        large_data = pd.DataFrame({
            'col_' + str(i): np.random.randn(1000) for i in range(100)
        })
        
        processor = SRAGDataProcessor()
        
        # Deve processar sem crash mesmo com dados grandes
        try:
            result = processor._optimize_memory_usage(large_data)
            assert isinstance(result, pd.DataFrame)
        except MemoryError:
            pytest.skip("Sistema com pouca memória disponível")
        except Exception as e:
            pytest.fail(f"Erro não esperado sob pressão de memória: {e}")